Workbook
Name Slicer_Department: #N/A
Name Slicer_Emp_ID: #N/A

Sheet Staff
A1: Emp ID | B1: Name | C1: Gender | D1: Department | E1: Salary | F1: Start Date | G1: FTE | H1: Employee type | I1: Work location | J1: Mobile Number
A2: XW68029 | B2: Michael Davis | C2: Female | D2: Operations | E2: 120000 | F2: 12-Nov-18 | G2: 1 | H2: Permanent | I2: Dubai, UAE | J2: 816.847.4201
A3: LK95323 | B3: David Edwards | C3: Male | D3: IT | E3: 98000 | F3: 43710 | G3: 0.9 | H3: Permanent | I3: Sydney, Australia | J3: 995.618.0161
A4: LE46327 | B4: Laura Lawrence | C4: Male | D4: Marketing | E4: 120000 | F4: 43902 | G4: 0.9 | H4: Permanent | I4: Tokyo, Japan | J4: 570.420.2367
A5: RN56442 | B5: Andrew Hardin | C5: Male | D5: Sales | E5: 20000 | F5: Mar 5, 2018 | G5: 1 | H5: Fixed Term | I5: Tokyo, Japan | J5: +1-599-129-8373
A6: QQ53474 | B6: Monique Diaz | C6: Female | D6: HR | E6: 57002.02 | F6: 2-Apr-18 | G6: 0.7 | H6: Permanent | I6: Delhi, India | J6: 610.453.2915x2013
A7: WL99915 | B7: Dawn Howell | C7: Female | D7: Operations | E7: 118976.16 | F7: Oct 16, 2020 | G7: 1 | H7: Permanent | I7: Delhi, India | J7: 956.154.2970
A8: OQ02176 | B8: Veronica Bell | C8: Female | D8: IT | E8: 104802.63 | F8: 44502 | G8: 1 | H8: Permanent | I8: New York, USA | J8: 273-874-8920
A9: GO15901 | B9: Jennifer Whitaker | C9: Male | D9: IT | E9: 66017.18 | F9: 43643 | G9: 0.9 | H9: Permanent | I9: Tokyo, Japan | J9: 522.348.5582
A10: XG85466 | B10: Elizabeth Martin | C10: Male | D10: Operations | E10: 74279.01 | F10: 43466 | G10: 1 | H10: Permanent | I10: Tokyo, Japan | J10: 041-835-5373x088
A11: KU43954 | B11: Robert Powers | C11: Male | D11: Sales | E11: 68980.52 | F11: 43494 | G11: 0.8 | H11: Permanent | I11: Delhi, India | J11: 001-761-379-7521
A12: PA66331 | B12: Tiffany White | C12: Female | D12: Customer Support | E12: 42314.39 | F12: Oct 18, 2021 | G12: 1 | H12: Fixed Term | I12: Dubai, UAE | J12: (689)259-3312x05590
A13: VL09949 | B13: Alex Jones | C13: Female | D13: HR | E13: 114425.19 | F13: 27-Jan-20 | G13: 1 | H13: Permanent | I13: London, UK | J13: 5124016835
A14: SB06299 | B14: Troy Swanson | C14: Male | D14: R&D | E14: 69192.85 | F14: 19-Apr-21 | G14: 1 | H14: Permanent | I14: New York, USA | J14: (598)445-9100x4931
A15: XO85866 | B15: Diane Wilson | C15: Male | D15: Finance | E15: 61214.26 | F15: 12-Mar-18 | G15: 1 | H15: Temporary | I15: New York, USA | J15: 927.499.9416x4491
A16: DU89321 | B16: Tammy Castaneda | C16: Female | D16: IT | E16: 54137.05 | F16: 25-Oct-19 | G16: 1 | H16: Permanent | I16: Delhi, India | J16: 001-337-748-3545x048
A17: JR86717 | B17: Benjamin Johnson | C17: Male | D17: Sales | E17: 37902.35 | F17: Dec 24, 2019 | G17: 1 | H17: Permanent | I17: Dubai, UAE | J17: 068.201.8632x06883
A18: NJ94299 | B18: Paul Clark | C18: Female | D18: IT | E18: 39969.72 | F18: 10-Dec-18 | G18: 1 | H18: Temporary | I18: Dubai, UAE | J18: +1-523-072-2087x0237
A19: UC33862 | B19: Stephanie Baxter | C19: Male | D19: Finance | E19: 69913.39 | F19: 43584 | G19: 1 | H19: Permanent | I19: Delhi, India | J19: 999.554.9734
A20: NT91504 | B20: Tammy Harrison | C20: Male | D20: IT | E20: 52748.63 | F20: 27-Jan-20 | G20: 1 | H20: Permanent | I20: New York, USA | J20: 569-862-2594x3605
A21: BV55499 | B21: David Moss | C21: Male | D21: Customer Support | E21: 50310.09 | F21: 44285 | G21: 0.4 | H21: Permanent | I21: Berlin, Germany | J21: (125)496-5407x20213
A22: LR64833 | B22: Stephanie Garcia | C22: Female | D22: Sales | E22: 52963.65 | F22: 44288 | G22: 0.3 | H22: Permanent | I22: London, UK | J22: 024.625.4622
A23: FB32796 | B23: Megan Patton | C23: Female | D23: Finance | E23: 62195.47 | F23: 26-Aug-21 | G23: 1 | H23: Permanent | I23: Toronto, Canada | J23: (382)627-6669x817
A24: GM34017 | B24: Sue Arnold | C24: Male | D24: Marketing | E24: 43329.22 | F24: 43809 | G24: 0.5 | H24: Fixed Term | I24: Berlin, Germany | J24: 423.901.3064x8235
A25: WB03411 | B25: Chelsea Barrett | C25: Female | D25: Marketing | E25: 71570.99 | F25: 22-Feb-21 | G25: 0.5 | H25: Permanent | I25: Toronto, Canada | J25: 472-078-6959x9182
A26: MT99677 | B26: Stephanie Fitzgerald | C26: Female | D26: IT | E26: 78840.23 | F26: 43633 | G26: 1 | H26: Temporary | I26: Toronto, Canada | J26: 633.253.6521x76983
A27: AE32607 | B27: Alexis Webb | C27: Male | D27: Finance | E27: 61994.76 | F27: 43794 | G27: 0.3 | H27: Permanent | I27: Toronto, Canada | J27: +1-638-076-7975x24762
A28: ZN82199 | B28: Samuel Bautista | C28: Male | D28: Operations | E28: 89690.38 | F28: 43206 | G28: 1 | H28: Permanent | I28: London, UK | J28: +1-068-607-0062
A29: QI20990 | B29: David Taylor | C29: Male | D29: Customer Support | E29: 104335.04 | F29: 43874 | G29: 1 | H29: Permanent | I29: Toronto, Canada | J29: 661-506-4188
A30: ZR99436 | B30: Crystal Torres | C30: Male | D30: Customer Support | E30: 52246.29 | F30: 18-Apr-19 | G30: 1 | H30: Temporary | I30: New York, USA | J30: +1-014-251-3180
A31: VC04606 | B31: William Larson | C31: Female | D31: Customer Support | E31: 90697.67 | F31: 44221 | G31: 0.8 | H31: Permanent | I31: Dubai, UAE | J31: (249)393-6520x6093
A32: IF05899 | B32: Derek Anderson | C32: Female | D32: HR | E32: 90884.32 | F32: 27-Dec-19 | G32: 1 | H32: Permanent | I32: Sydney, Australia | J32: 358.628.7693
A33: AF68524 | B33: Michael Moreno | C33: Female | D33: Marketing | E33: 76320.44 | F33: 44383 | G33: 0.8 | H33: Temporary | I33: Dubai, UAE | J33: +1-897-779-6202x662
A34: VY40784 | B34: Holly Lee | C34: Female | D34: Marketing | E34: 73360.38 | F34: 43972 | G34: 1 | H34: Temporary | I34: Tokyo, Japan | J34: 690.739.4644x3973
A35: EM61484 | B35: Angela Yoder DDS | C35: Male | D35: IT | F35: Aug 12, 2020 | G35: 0.7 | H35: Permanent | I35: Berlin, Germany | J35: (518)538-0250x80138
A36: CL14522 | B36: Richard Chan | C36: Female | D36: Customer Support | E36: 50449.46 | F36: 14-Nov-18 | G36: 0.8 | H36: Permanent | I36: Delhi, India | J36: 001-045-065-1755x610
A37: HH09005 | B37: Kelly Cohen | C37: Female | D37: Finance | E37: 53949.26 | F37: 43808 | G37: 1 | H37: Temporary | I37: Berlin, Germany | J37: 001-223-915-9373x8259
A38: QD19386 | B38: Scott Ramos | C38: Female | D38: IT | E38: 113616.23 | F38: 43255 | G38: 1 | H38: Permanent | I38: New York, USA | J38: 8604009418
A39: QK84068 | B39: Suzanne Ali | C39: Female | D39: Operations | E39: 110906.35 | F39: Nov 30, 2018 | G39: 1 | H39: Temporary | I39: Sydney, Australia | J39: 001-634-043-5907x19985
A40: JF96988 | B40: Adrian Estrada | C40: Male | D40: Customer Support | E40: 100371.31 | F40: 44067 | G40: 0.8 | H40: Fixed Term | I40: New York, USA | J40: 4365766578
...

Sheet EMP_TABLE
A1: Emp ID | B1: Fname | C1: Lname | D1: Gender | E1: Department | F1: Salary | G1: Start Date | H1: FTE | I1: Employee type | J1: Work location | K1: Mobile Number
A2: XW68029 | B2: Michael | C2: Davis | D2: Female | E2: Operations | F2: 120000 | G2: 43416 | H2: 1 | I2: Permanent | J2: Dubai, UAE | K2: 8168474201
A3: LK95323 | B3: David | C3: Edwards | D3: Male | E3: IT | F3: 98000 | G3: 43710 | H3: 0.9 | I3: Permanent | J3: Sydney, Australia | K3: 9956180161
A4: LE46327 | B4: Laura | C4: Lawrence | D4: Male | E4: Marketing | F4: 120000 | G4: 43902 | H4: 0.9 | I4: Permanent | J4: Tokyo, Japan | K4: 5704202367
A5: RN56442 | B5: Andrew | C5: Hardin | D5: Male | E5: Sales | F5: 20000 | G5: 43164 | H5: 1 | I5: Fixed Term | J5: Tokyo, Japan | K5: +1-599-129-8373
A6: QQ53474 | B6: Monique | C6: Diaz | D6: Female | E6: HR | F6: 57002.02 | G6: 43192 | H6: 0.7 | I6: Permanent | J6: Delhi, India | K6: 61045329152013
A7: WL99915 | B7: Dawn | C7: Howell | D7: Female | E7: Operations | F7: 118976.16 | G7: 44120 | H7: 1 | I7: Permanent | J7: Delhi, India | K7: 9561542970
A8: OQ02176 | B8: Veronica | C8: Bell | D8: Female | E8: IT | F8: 104802.63 | G8: 44502 | H8: 1 | I8: Permanent | J8: New York, USA | K8: 273-874-8920
A9: GO15901 | B9: Jennifer | C9: Whitaker | D9: Male | E9: IT | F9: 66017.18 | G9: 43643 | H9: 0.9 | I9: Permanent | J9: Tokyo, Japan | K9: 5223485582
A10: XG85466 | B10: Elizabeth | C10: Martin | D10: Male | E10: Operations | F10: 74279.01 | G10: 43466 | H10: 1 | I10: Permanent | J10: Tokyo, Japan | K10: 041-835-5373088
A11: KU43954 | B11: Robert | C11: Powers | D11: Male | E11: Sales | F11: 68980.52 | G11: 43494 | H11: 0.8 | I11: Permanent | J11: Delhi, India | K11: 001-761-379-7521
A12: PA66331 | B12: Tiffany | C12: White | D12: Female | E12: Customer Support | F12: 42314.39 | G12: 44487 | H12: 1 | I12: Fixed Term | J12: Dubai, UAE | K12: (689)259-331205590
A13: VL09949 | B13: Alex | C13: Jones | D13: Female | E13: HR | F13: 114425.19 | G13: 43857 | H13: 1 | I13: Permanent | J13: London, UK | K13: 5124016835
A14: SB06299 | B14: Troy | C14: Swanson | D14: Male | E14: R&D | F14: 69192.85 | G14: 44305 | H14: 1 | I14: Permanent | J14: New York, USA | K14: (598)445-91004931
... A261: FQ07827 | B261: Andre | C261: Lewis | D261: Male | E261: Marketing | F261: 78020.39 | G261: 43899 | H261: 1 | I261: Permanent | J261: Tokyo, Japan | K261: +1-965-985-3158

Sheet BASIC QUESTIONS
A1: Q1- GENERATE THE LIST OF ALL UNIQUE DEPARTMENTS WITHIN THE ORGANIZATION ?
B3: DEPARTMENTS
B4: {=_xlfn.UNIQUE(EMP_TABLE[Department])} -> Operations
B5: IT
B6: Marketing
B7: Sales
B8: HR
B9: Customer Support
B10: R&D
B11: Finance
A13: Q2- HOW MANY EMPLOYEES ARE CURRENTLY ASSIGN IN GERMANY ? | H13: =COUNTIF(EMP_TABLE[Work location],"*GERMANY") -> 37
A15: Q3- CALCULATE THE TOTAL SALARY PAID TO EMPLOYEES WORKING IN 'HR' DEPARTMENT? | J15: =SUMIF(EMP_TABLE[Department],"HR",EMP_TABLE[Salary]) -> 2292324
A17: Q4- DETERMINE THE AVERAGE SALARY OF THE EMPLOYEE WORKING IN 'IT DEPARTMENT' ? | J17: =AVERAGEIF(EMP_TABLE[Department],"IT",EMP_TABLE[Salary]) -> 81480.678
A19: Q5- FIND THE AVERAGE SALARY OF MALE EMPLOYEE WORKING IN FIXED TERM ? | J19: =AVERAGEIFS(EMP_TABLE[Salary],EMP_TABLE[Gender],"MALE",EMP_TABLE[Employee type],"FIXED TERM") -> 74129.803
A21: Q6- LIST OF WMPLOYEE FROM MARKETING DEPARTMENT WHO EARN MORE THAN 50000? | J21: EMPLOYEE
J22: {=_xlfn._xlws.FILTER(EMP_TABLE[Fname],(EMP_TABLE[Department]="MARKETING")*(EMP_TABLE[Salary]>50000))} -> Laura
J23: Chelsea
J24: Michael
J25: Holly
J26: Cheryl
J27: Joseph
J28: Sally
J29: Emily
J30: Jim
J31: Melissa
J32: Sara
J33: Heather
J34: Jeremy
... J41: Andre

Sheet REPORT
D3: DEPARTMENT REPORT
D5: DEPARTMENT | E5: TOTAL EMPLOYEE | F5: AVERAGE PAY | G5: %DIFF FROM COMPANY AVG. | H5: HIGHEST SALARY | I5: MEDIUM SALARY | J5: HIGH EARNER>100K | K5: PAY RANKING
D6: {=_xlfn.UNIQUE(EMP_TABLE[Department])} -> Operations | E6: =COUNTIF(EMP_TABLE[Department],D6) -> 42 | F6: =AVERAGEIF(EMP_TABLE[Department],D6,EMP_TABLE[Salary]) -> 73760.583 | G6: =F6-AVERAGE(EMP_TABLE[Salary]) -> 180.52023 | H6: =_xlfn.MAXIFS(EMP_TABLE[Salary],EMP_TABLE[Department],D6) -> 120000 | I6: {=MEDIAN(_xlfn._xlws.FILTER(EMP_TABLE[Salary],EMP_TABLE[Department]=D6))} -> 77341.01 | J6: =COUNTIFS(EMP_TABLE[Department],D6,EMP_TABLE[Salary],">100000") -> 6 | K6: =_xlfn.RANK.EQ(F6,F6:F13) -> 5
D7: IT | E7: =COUNTIF(EMP_TABLE[Department],D7) -> 27 | F7: =AVERAGEIF(EMP_TABLE[Department],D7,EMP_TABLE[Salary]) -> 81480.678 | G7: =F7-AVERAGE(EMP_TABLE[Salary]) -> 7900.6154 | H7: =_xlfn.MAXIFS(EMP_TABLE[Salary],EMP_TABLE[Department],D7) -> 119022.49 | I7: {=MEDIAN(_xlfn._xlws.FILTER(EMP_TABLE[Salary],EMP_TABLE[Department]=D7))} -> 78840.23 | J7: =COUNTIFS(EMP_TABLE[Department],D7,EMP_TABLE[Salary],">100000") -> 10 | K7: =_xlfn.RANK.EQ(F7,F7:F14) -> 1
D8: Marketing | E8: =COUNTIF(EMP_TABLE[Department],D8) -> 26 | F8: =AVERAGEIF(EMP_TABLE[Department],D8,EMP_TABLE[Salary]) -> 77364.539 | G8: =F8-AVERAGE(EMP_TABLE[Salary]) -> 3784.4765 | H8: =_xlfn.MAXIFS(EMP_TABLE[Salary],EMP_TABLE[Department],D8) -> 120000 | I8: {=MEDIAN(_xlfn._xlws.FILTER(EMP_TABLE[Salary],EMP_TABLE[Department]=D8))} -> 77170.415 | J8: =COUNTIFS(EMP_TABLE[Department],D8,EMP_TABLE[Salary],">100000") -> 6 | K8: =_xlfn.RANK.EQ(F8,F8:F15) -> 1
D9: Sales | E9: =COUNTIF(EMP_TABLE[Department],D9) -> 38 | F9: =AVERAGEIF(EMP_TABLE[Department],D9,EMP_TABLE[Salary]) -> 66766.354 | G9: =F9-AVERAGE(EMP_TABLE[Salary]) -> -6813.7079 | H9: =_xlfn.MAXIFS(EMP_TABLE[Salary],EMP_TABLE[Department],D9) -> 114691.03 | I9: {=MEDIAN(_xlfn._xlws.FILTER(EMP_TABLE[Salary],EMP_TABLE[Department]=D9))} -> 68443.16 | J9: =COUNTIFS(EMP_TABLE[Department],D9,EMP_TABLE[Salary],">100000") -> 4 | K9: =_xlfn.RANK.EQ(F9,F9:F16) -> 5
D10: HR | E10: =COUNTIF(EMP_TABLE[Department],D10) -> 31 | F10: =AVERAGEIF(EMP_TABLE[Department],D10,EMP_TABLE[Salary]) -> 73945.937 | G10: =F10-AVERAGE(EMP_TABLE[Salary]) -> 365.87439 | H10: =_xlfn.MAXIFS(EMP_TABLE[Salary],EMP_TABLE[Department],D10) -> 114425.19 | I10: {=MEDIAN(_xlfn._xlws.FILTER(EMP_TABLE[Salary],EMP_TABLE[Department]=D10))} -> 71371.37 | J10: =COUNTIFS(EMP_TABLE[Department],D10,EMP_TABLE[Salary],">100000") -> 6 | K10: =_xlfn.RANK.EQ(F10,F10:F17) -> 2
D11: Customer Support | E11: =COUNTIF(EMP_TABLE[Department],D11) -> 40 | F11: =AVERAGEIF(EMP_TABLE[Department],D11,EMP_TABLE[Salary]) -> 71094.642 | G11: =F11-AVERAGE(EMP_TABLE[Salary]) -> -2485.4201 | H11: =_xlfn.MAXIFS(EMP_TABLE[Salary],EMP_TABLE[Department],D11) -> 116767.63 | I11: {=MEDIAN(_xlfn._xlws.FILTER(EMP_TABLE[Salary],EMP_TABLE[Department]=D11))} -> 69410.71 | J11: =COUNTIFS(EMP_TABLE[Department],D11,EMP_TABLE[Salary],">100000") -> 8 | K11: =_xlfn.RANK.EQ(F11,F11:F18) -> 3
D12: R&D | E12: =COUNTIF(EMP_TABLE[Department],D12) -> 27 | F12: =AVERAGEIF(EMP_TABLE[Department],D12,EMP_TABLE[Salary]) -> 75719.626 | G12: =F12-AVERAGE(EMP_TABLE[Salary]) -> 2139.5632 | H12: =_xlfn.MAXIFS(EMP_TABLE[Salary],EMP_TABLE[Department],D12) -> 114465.93 | I12: {=MEDIAN(_xlfn._xlws.FILTER(EMP_TABLE[Salary],EMP_TABLE[Department]=D12))} -> 80695.74 | J12: =COUNTIFS(EMP_TABLE[Department],D12,EMP_TABLE[Salary],">100000") -> 3 | K12: =_xlfn.RANK.EQ(F12,F12:F19) -> 1
D13: Finance | E13: =COUNTIF(EMP_TABLE[Department],D13) -> 29 | F13: =AVERAGEIF(EMP_TABLE[Department],D13,EMP_TABLE[Salary]) -> 72543.253 | G13: =F13-AVERAGE(EMP_TABLE[Salary]) -> -1036.8089 | H13: =_xlfn.MAXIFS(EMP_TABLE[Salary],EMP_TABLE[Department],D13) -> 114772.32 | I13: {=MEDIAN(_xlfn._xlws.FILTER(EMP_TABLE[Salary],EMP_TABLE[Department]=D13))} -> 69913.39 | J13: =COUNTIFS(EMP_TABLE[Department],D13,EMP_TABLE[Salary],">100000") -> 4 | K13: =_xlfn.RANK.EQ(F13,F13:F20) -> 1

Sheet LOOKUP_FUNC
A1: EMP ID | B1: VLOOKUP | C1: XLOOKUP | D1: MATCHING | E1: INDEX | F1: HLOOKUP
B2: NAME | C2: WORK LOCATION | D2: INDEX NO. | E2: DEPARTMENT | F2: NAME | G2: HLOOUP IS FOR HORIZONTAL DATA AS OUR DATA IS VERTICALLY STORE SO WE USE XLOOKUP OR VLOOKUP
A3: LK95323 | B3: =VLOOKUP(A3,EMP_TABLE[],2,FALSE) -> David | C3: =_xlfn.XLOOKUP(A3,EMP_TABLE[Emp ID],EMP_TABLE[Work location],"INVALID EMP_ID") -> Sydney, Australia | D3: =MATCH(A3,EMP_TABLE[Emp ID],0) -> 2 | E3: {=INDEX(EMP_TABLE[Department],D3)} -> IT
A8: ALL DETAILS BY XLOOKUP
A9: EMP_ID | B9: F_NAME | C9: L_NAME | D9: GENDER | E9: DEPARTMENT | F9: SALARY | G9: START_DATE | H9: FTE | I9: EMPLOYEE_TYPE | J9: WORK_LOCATION | K9: MOBILE_NUMBER
A10: =_xlfn.XLOOKUP(A3,EMP_TABLE[Emp ID],EMP_TABLE[Emp ID],"INVAALID ID") -> LK95323 | B10: =_xlfn.XLOOKUP(A10,EMP_TABLE[Emp ID],EMP_TABLE[Fname],"ENTER A VALID EMP_ID") -> David | C10: =_xlfn.XLOOKUP(A10,EMP_TABLE[Emp ID],EMP_TABLE[Lname],"ENTER A VALID EMP_ID") -> Edwards | D10: =_xlfn.XLOOKUP(A10,EMP_TABLE[Emp ID],EMP_TABLE[Gender],"ENTER A VALID EMP_ID") -> Male | E10: =_xlfn.XLOOKUP(A10,EMP_TABLE[Emp ID],EMP_TABLE[Department],"ENTER A VALID EMP_ID") -> IT | F10: =_xlfn.XLOOKUP(A10,EMP_TABLE[Emp ID],EMP_TABLE[Salary],"ENTER A VALID EMP_ID") -> 98000 | G10: =_xlfn.XLOOKUP(A10,EMP_TABLE[Emp ID],EMP_TABLE[Start Date],"ENTER A VALID EMP_ID") -> 43710 | H10: =_xlfn.XLOOKUP(A10,EMP_TABLE[Emp ID],EMP_TABLE[FTE],"ENTER A VALID EMP_ID") -> 0.9 | I10: =_xlfn.XLOOKUP(A10,EMP_TABLE[Emp ID],EMP_TABLE[Employee type],"ENTER A VALID EMP_ID") -> Permanent | J10: =_xlfn.XLOOKUP(A10,EMP_TABLE[Emp ID],EMP_TABLE[Work location],"ENTER A VALID EMP_ID") -> Sydney, Australia | K10: =_xlfn.XLOOKUP(A10,EMP_TABLE[Emp ID],EMP_TABLE[Mobile Number],"ENTER A VALID EMP_ID") -> 9956180161
A11: {=_xlfn.XLOOKUP(A3,EMP_TABLE[Emp ID],EMP_TABLE[],"INVALID EMP_ID")} -> LK95323 | B11: David | C11: Edwards | D11: Male | E11: IT | F11: 98000 | G11: 43710 | H11: 0.9 | I11: Permanent | J11: Sydney, Australia | K11: 9956180161
A14: SALARY >= 120 | I14: NAME | K14: NAME OF THE PERSON JISKE SALARY MAX HO
A15: BY XLOOKUP | B15: {=_xlfn.XLOOKUP(TRUE,EMP_TABLE[Salary]>=120000,EMP_TABLE[Emp ID])} -> XW68029 | C15: ONLY RETURN THE FIRST VALUE FIND | I15: BY XLOOKUP | J15: {=_xlfn.XLOOKUP(MAX(EMP_TABLE[Salary]),EMP_TABLE[Salary],EMP_TABLE[Fname]&" "& EMP_TABLE[Lname])} -> Michael Davis
A16: BY FILTER | B16: {=_xlfn._xlws.FILTER(EMP_TABLE[Emp ID],EMP_TABLE[Salary]>=120000)} -> XW68029 | I16: BY FILTER | J16: {=_xlfn._xlws.FILTER(EMP_TABLE[Fname]&" "&EMP_TABLE[Lname],EMP_TABLE[Salary]=MAX(EMP_TABLE[Salary]))} -> Michael Davis
B17: LE46327 | C17: RETURN ALL THE ROWS WHICH WERE TRUE | J17: Laura Lawrence

Sheet SALES_TABLE
A1: Product | B1: Region | C1: Employee | D1: Month | E1: Quantity | F1: Price | G1: Sales
A2: Monitor | B2: North | C2: Raj | D2: Feb | E2: 10 | F2: 23149 | G2: 231490
A3: Headset | B3: South | C3: Mohit | D3: Jun | E3: 3 | F3: 2893 | G3: 8679
A4: Laptop | B4: East | C4: Simran | D4: Jan | E4: 10 | F4: 8806 | G4: 88060
A5: Headset | B5: South | C5: Simran | D5: May | E5: 6 | F5: 10978 | G5: 65868
A6: Monitor | B6: North | C6: Anjali | D6: Mar | E6: 5 | F6: 8777 | G6: 43885
A7: Keyboard | B7: East | C7: Riya | D7: Jun | E7: 5 | F7: 14359 | G7: 71795
A8: Keyboard | B8: South | C8: Mohit | D8: Feb | E8: 4 | F8: 15337 | G8: 138033
A9: Keyboard | B9: South | C9: Simran | D9: Apr | E9: 8 | F9: 14135 | G9: 113080
A10: Mouse | B10: East | C10: Anjali | D10: Jun | E10: 4 | F10: 29761 | G10: 119044
A11: Headset | B11: South | C11: Raj | D11: Feb | E11: 6 | F11: 3667 | G11: 22002
A12: Laptop | B12: East | C12: Raj | D12: May | E12: 7 | F12: 20079 | G12: 140553
A13: Monitor | B13: North | C13: Mohit | D13: Mar | E13: 4 | F13: 10486 | G13: 41944
... A1001: Monitor | B1001: North | C1001: Mohit | D1001: Apr | E1001: 8 | F1001: 26072 | G1001: 208576

Sheet PIVOT_TABLES
A1: PIVOT TABLES
A3: ** We are planning to allocate next quarter's budget. Can you tell me how much total revenue each region generated?
A6: Row Labels | B6: Sum of Sales
A7: East | B7: 21307793
A8: North | B8: 20360183
A9: South | B9: 23456425
A10: West | B10: 19548235
A11: Grand Total | B11: 84672636
A14: ** Management wants a quick summary: How many units of each product did we sell, and what was their average selling price?
A16: Row Labels | B16: Count of Quantity | C16: Sum of Sales
A17: Headset | B17: 207 | C17: 16258754
A18: Keyboard | B18: 195 | C18: 16025283
A19: Laptop | B19: 212 | C19: 18646830
A20: Monitor | B20: 195 | C20: 17914877
A21: Mouse | B21: 191 | C21: 15826892
A22: Grand Total | B22: 1000 | C22: 84672636
A24: ** We need to understand monthly sales trends to adjust our marketing efforts. Can you show how our total sales varied month-by-month?
A26: Row Labels | B26: Sum of Sales
A27: Jan | B27: 12272270
A28: Feb | B28: 14745990
A29: Mar | B29: 14200255
A30: Apr | B30: 14008599
A31: May | B31: 14263988
A32: Jun | B32: 15181534
A33: Grand Total | B33: 84672636
A36: ** Which salesperson is doing well in which region? We’re considering performance-based bonuses.
A38: Sum of Sales | B38: Column Labels
A39: Row Labels | B39: East | C39: North | D39: South | E39: West | F39: Grand Total
A40: Anjali | B40: 0.043953881 | C40: 0.039703134 | D40: 0.043040269 | E40: 0.050739675 | F40: 0.17743696
A41: Mohit | B41: 0.054254033 | C41: 0.061109955 | D41: 0.056181704 | E41: 0.049775939 | F41: 0.22132163
A42: Raj | B42: 0.06071892 | C42: 0.055765312 | D42: 0.056603883 | E42: 0.041238931 | F42: 0.21432705
A43: Riya | B43: 0.042477454 | C43: 0.036180012 | D43: 0.064259615 | E43: 0.039523548 | F43: 0.18244063
A44: Simran | B44: 0.050244816 | C44: 0.047699235 | D44: 0.056939387 | E44: 0.049590295 | F44: 0.20447373
A45: Grand Total | B45: 0.2516491 | C45: 0.24045765 | D45: 0.27702486 | E45: 0.23086839 | F45: 1
A48: We want to focus on our best-selling products. Can you list the top 3 products based on total sales?
A50: Row Labels | B50: Sum of Sales
A51: Headset | B51: 16258754
A52: Laptop | B52: 18646830
A53: Monitor | B53: 17914877
A54: Grand Total | B54: 52820461
...

Sheet Dashbord_Table
A1: 📊 Employee Performance Dataset
A2: Emp ID | B2: Name | C2: Gender | D2: Department | E2: Location | F2: Role | G2: Experience (Years) | H2: Annual Salary | I2: Target | J2: Achieved | K2: Achievement | L2: Rank | M2: Experience Group
A3: E101 | B3: James Anderson | C3: Male | D3: Finance | E3: New York | F3: Analyst | G3: 7 | H3: 92000 | I3: 180000 | J3: 175000 | K3: =DASHBOARD_TABLE[[#This Row],[Achieved]]/DASHBOARD_TABLE[[#This Row],[Target ]] -> 0.97222222 | L3: =_xlfn.RANK.EQ(DASHBOARD_TABLE[[#This Row],[Achievement]], DASHBOARD_TABLE[Achievement]) -> 6 | M3: {=_xlfn.IFS(DASHBOARD_TABLE[[#This Row],[Experience (Years)]]<=3, "Junior", DASHBOARD_TABLE[[#This Row],[Experience (Years)]]<=7, "Mid-Level", DASHBOARD_TABLE[[#This Row],[Experience (Years)]]>7, "Senior")} -> Mid-Level
A4: E102 | B4: Olivia Martin | C4: Female | D4: IT | E4: Chicago | F4: Executive | G4: 3 | H4: 62000 | I4: 100000 | J4: 110000 | K4: =DASHBOARD_TABLE[[#This Row],[Achieved]]/DASHBOARD_TABLE[[#This Row],[Target ]] -> 1.1 | L4: =_xlfn.RANK.EQ(DASHBOARD_TABLE[[#This Row],[Achievement]], DASHBOARD_TABLE[Achievement]) -> 1 | M4: {=_xlfn.IFS(DASHBOARD_TABLE[[#This Row],[Experience (Years)]]<=3, "Junior", DASHBOARD_TABLE[[#This Row],[Experience (Years)]]<=7, "Mid-Level", DASHBOARD_TABLE[[#This Row],[Experience (Years)]]>7, "Senior")} -> Junior
A5: E103 | B5: William Scott | C5: Male | D5: HR | E5: Houston | F5: Consultant | G5: 10 | H5: 78000 | I5: 140000 | J5: 120000 | K5: =DASHBOARD_TABLE[[#This Row],[Achieved]]/DASHBOARD_TABLE[[#This Row],[Target ]] -> 0.85714286 | L5: =_xlfn.RANK.EQ(DASHBOARD_TABLE[[#This Row],[Achievement]], DASHBOARD_TABLE[Achievement]) -> 10 | M5: {=_xlfn.IFS(DASHBOARD_TABLE[[#This Row],[Experience (Years)]]<=3, "Junior", DASHBOARD_TABLE[[#This Row],[Experience (Years)]]<=7, "Mid-Level", DASHBOARD_TABLE[[#This Row],[Experience (Years)]]>7, "Senior")} -> Senior
A6: E104 | B6: Ava Thompson | C6: Female | D6: Marketing | E6: Phoenix | F6: Manager | G6: 5 | H6: 105000 | I6: 150000 | J6: 145000 | K6: =DASHBOARD_TABLE[[#This Row],[Achieved]]/DASHBOARD_TABLE[[#This Row],[Target ]] -> 0.96666667 | L6: =_xlfn.RANK.EQ(DASHBOARD_TABLE[[#This Row],[Achievement]], DASHBOARD_TABLE[Achievement]) -> 7 | M6: {=_xlfn.IFS(DASHBOARD_TABLE[[#This Row],[Experience (Years)]]<=3, "Junior", DASHBOARD_TABLE[[#This Row],[Experience (Years)]]<=7, "Mid-Level", DASHBOARD_TABLE[[#This Row],[Experience (Years)]]>7, "Senior")} -> Mid-Level
A7: E105 | B7: Benjamin Carter | C7: Male | D7: Sales | E7: Los Angeles | F7: Manager | G7: 8 | H7: 112000 | I7: 200000 | J7: 210000 | K7: =DASHBOARD_TABLE[[#This Row],[Achieved]]/DASHBOARD_TABLE[[#This Row],[Target ]] -> 1.05 | L7: =_xlfn.RANK.EQ(DASHBOARD_TABLE[[#This Row],[Achievement]], DASHBOARD_TABLE[Achievement]) -> 2 | M7: {=_xlfn.IFS(DASHBOARD_TABLE[[#This Row],[Experience (Years)]]<=3, "Junior", DASHBOARD_TABLE[[#This Row],[Experience (Years)]]<=7, "Mid-Level", DASHBOARD_TABLE[[#This Row],[Experience (Years)]]>7, "Senior")} -> Senior
A8: E106 | B8: Emily White | C8: Female | D8: Operations | E8: New York | F8: Executive | G8: 4 | H8: 67000 | I8: 100000 | J8: 90000 | K8: =DASHBOARD_TABLE[[#This Row],[Achieved]]/DASHBOARD_TABLE[[#This Row],[Target ]] -> 0.9 | L8: =_xlfn.RANK.EQ(DASHBOARD_TABLE[[#This Row],[Achievement]], DASHBOARD_TABLE[Achievement]) -> 9 | M8: {=_xlfn.IFS(DASHBOARD_TABLE[[#This Row],[Experience (Years)]]<=3, "Junior", DASHBOARD_TABLE[[#This Row],[Experience (Years)]]<=7, "Mid-Level", DASHBOARD_TABLE[[#This Row],[Experience (Years)]]>7, "Senior")} -> Mid-Level
A9: E107 | B9: Lucas Hernandez | C9: Male | D9: Finance | E9: Chicago | F9: Analyst | G9: 9 | H9: 88000 | I9: 160000 | J9: 158000 | K9: =DASHBOARD_TABLE[[#This Row],[Achieved]]/DASHBOARD_TABLE[[#This Row],[Target ]] -> 0.9875 | L9: =_xlfn.RANK.EQ(DASHBOARD_TABLE[[#This Row],[Achievement]], DASHBOARD_TABLE[Achievement]) -> 4 | M9: {=_xlfn.IFS(DASHBOARD_TABLE[[#This Row],[Experience (Years)]]<=3, "Junior", DASHBOARD_TABLE[[#This Row],[Experience (Years)]]<=7, "Mid-Level", DASHBOARD_TABLE[[#This Row],[Experience (Years)]]>7, "Senior")} -> Senior
A10: E108 | B10: Sophia Lewis | C10: Female | D10: HR | E10: Houston | F10: Consultant | G10: 6 | H10: 74000 | I10: 120000 | J10: 120000 | K10: =DASHBOARD_TABLE[[#This Row],[Achieved]]/DASHBOARD_TABLE[[#This Row],[Target ]] -> 1 | L10: =_xlfn.RANK.EQ(DASHBOARD_TABLE[[#This Row],[Achievement]], DASHBOARD_TABLE[Achievement]) -> 3 | M10: {=_xlfn.IFS(DASHBOARD_TABLE[[#This Row],[Experience (Years)]]<=3, "Junior", DASHBOARD_TABLE[[#This Row],[Experience (Years)]]<=7, "Mid-Level", DASHBOARD_TABLE[[#This Row],[Experience (Years)]]>7, "Senior")} -> Mid-Level
A11: E109 | B11: Masoni Walker | C11: Female | D11: IT | E11: Phoenix | F11: Executive | G11: 2 | H11: 59000 | I11: 90000 | J11: 85000 | K11: =DASHBOARD_TABLE[[#This Row],[Achieved]]/DASHBOARD_TABLE[[#This Row],[Target ]] -> 0.94444444 | L11: =_xlfn.RANK.EQ(DASHBOARD_TABLE[[#This Row],[Achievement]], DASHBOARD_TABLE[Achievement]) -> 8 | M11: {=_xlfn.IFS(DASHBOARD_TABLE[[#This Row],[Experience (Years)]]<=3, "Junior", DASHBOARD_TABLE[[#This Row],[Experience (Years)]]<=7, "Mid-Level", DASHBOARD_TABLE[[#This Row],[Experience (Years)]]>7, "Senior")} -> Junior
A12: E110 | B12: Isabella Hall | C12: Female | D12: Sales | E12: Los Angeles | F12: Analyst | G12: 11 | H12: 99000 | I12: 190000 | J12: 185000 | K12: =DASHBOARD_TABLE[[#This Row],[Achieved]]/DASHBOARD_TABLE[[#This Row],[Target ]] -> 0.97368421 | L12: =_xlfn.RANK.EQ(DASHBOARD_TABLE[[#This Row],[Achievement]], DASHBOARD_TABLE[Achievement]) -> 5 | M12: {=_xlfn.IFS(DASHBOARD_TABLE[[#This Row],[Experience (Years)]]<=3, "Junior", DASHBOARD_TABLE[[#This Row],[Experience (Years)]]<=7, "Mid-Level", DASHBOARD_TABLE[[#This Row],[Experience (Years)]]>7, "Senior")} -> Senior
A13: Total | H13: =SUBTOTAL(109,DASHBOARD_TABLE[[Annual Salary ]]) -> 836000 | K13: =SUBTOTAL(109,DASHBOARD_TABLE[Achievement]) -> 9.7516604

Sheet Dashboard_queries
C4: Dashboard Queries
C7: What is the average annual salary in each department?
C9: How does each department perform in terms of target vs actual achievement?
C11: One-Click Insights of Every Employee
C13: Which roles are achieving more % of their targets?
C15: MALE VS FEMALE RATIO ?
C17: Describe the experience-wise performance of staff.
C19: What is the salary gap between male and female employees in each role?

Sheet PIVOT_DASHBOARD
A3: What is the average annual salary in each department?
A5: Row Labels | B5: Average of Annual Salary
A6: Finance | B6: 92000
A7: Grand Total | B7: 92000
A14: How does each department perform in terms of target vs actual achievement?
A16: Row Labels | B16: Target. | C16: Sum
A17: Finance | B17: 180000 | C17: 175000
A18: Grand Total | B18: 180000 | C18: 175000
A26: One-Click Insights of Every Employee
K27: {=_xlfn.XLOOKUP(A29,DASHBOARD_TABLE[Emp ID],DASHBOARD_TABLE[])} -> E101 | L27: James Anderson | M27: Male | N27: Finance | O27: New York | P27: Analyst | Q27: 7 | R27: 92000 | S27: 180000 | T27: 175000 | U27: 0.97222222 | V27: 6 | W27: Mid-Level
A28: Row Labels
A29: E101
A30: Grand Total
A33: Which roles are achieving more % of their targets?
A35: Row Labels | B35: Sum of Achieved
A36: Analyst | B36: 1
A37: Grand Total | B37: 1
A43: MALE VS FEMALE RATIO ?
A45: Row Labels | B45: Count of Gender
A46: Male | B46: 1
A47: Grand Total | B47: 1
A51: Describe the experience-wise performance of staff.
A53: Row Labels | B53: Sum of Achievement
A54: Mid-Level | B54: 1
A55: Grand Total | B55: 1
A60: What is the salary gap between male and female employees in each role?
A62: Sum of Annual Salary | B62: Column Labels
A63: Row Labels | B63: Male | C63: Grand Total
A64: Analyst | B64: 92000 | C64: 92000
A65: Grand Total | B65: 92000 | C65: 92000

Sheet DASHBOARD
A1: =PIVOT_DASHBOARD!L27 -> James Anderson
A7: GENDER: | B7: =PIVOT_DASHBOARD!M27 -> Male
A10: DEPARTMENT: | B10: =PIVOT_DASHBOARD!N27 -> Finance
A14: ROLE: | B14: =PIVOT_DASHBOARD!P27 -> Analyst
A17: EXPERIENCE: | B17: =PIVOT_DASHBOARD!Q27 & " Year(s)" -> 7 Year(s)
A20: ANNUAL SALARY: | B20: =PIVOT_DASHBOARD!R27 -> 92000
A23: ACHIVEMENT: | B23: =PIVOT_DASHBOARD!U27 -> 0.97222222
A26: RANK: | B26: =PIVOT_DASHBOARD!V27 -> 6
A29: LOCATION: | B29: =PIVOT_DASHBOARD!O27 -> New York
